{"uuid": "d070f5a0-6b00-4879-9930-9f99cc78e680", "children": ["f0de525d-c93a-45ba-ae8f-7714549d6890"], "befores": [{"name": "setup", "status": "passed", "start": 1607114089666, "stop": 1607114094570}], "afters": [{"name": "setup::0", "status": "broken", "statusDetails": {"message": "selenium.common.exceptions.WebDriverException: Message: chrome not reachable\n  (Session info: chrome=86.0.4240.111)\n\n", "trace": "  File \"/home/dawood/PycharmProjects/pytestpoc/venv/lib/python3.6/site-packages/allure_commons/_allure.py\", line 197, in __call__\n    return self._fixture_function(*args, **kwargs)\n  File \"/home/dawood/PycharmProjects/pytestpoc/venv/lib/python3.6/site-packages/_pytest/fixtures.py\", line 939, in _teardown_yield_fixture\n    next(it)\n  File \"/home/dawood/PycharmProjects/Untitled Folder/pytestpoc/tests/test_login.py\", line 20, in setup\n    self.driver.close()\n  File \"/home/dawood/PycharmProjects/pytestpoc/venv/lib/python3.6/site-packages/selenium/webdriver/remote/webdriver.py\", line 688, in close\n    self.execute(Command.CLOSE)\n  File \"/home/dawood/PycharmProjects/pytestpoc/venv/lib/python3.6/site-packages/selenium/webdriver/remote/webdriver.py\", line 321, in execute\n    self.error_handler.check_response(response)\n  File \"/home/dawood/PycharmProjects/pytestpoc/venv/lib/python3.6/site-packages/selenium/webdriver/remote/errorhandler.py\", line 242, in check_response\n    raise exception_class(message, screen, stacktrace)\n"}, "start": 1607114095852, "stop": 1607114095855}], "start": 1607114089666, "stop": 1607114095855}